ERROR 2021-06-30 12:44:54,669 log 18 140492594870016 Internal Server Error: /pets/1/
Traceback (most recent call last):
  File "/usr/local/lib/python3.7/site-packages/django/core/handlers/exception.py", line 47, in inner
    response = get_response(request)
  File "/usr/local/lib/python3.7/site-packages/django/core/handlers/base.py", line 181, in _get_response
    response = wrapped_callback(request, *callback_args, **callback_kwargs)
  File "/usr/local/lib/python3.7/site-packages/django/views/decorators/csrf.py", line 54, in wrapped_view
    return view_func(*args, **kwargs)
  File "/usr/local/lib/python3.7/site-packages/django/views/generic/base.py", line 70, in view
    return self.dispatch(request, *args, **kwargs)
  File "/usr/local/lib/python3.7/site-packages/rest_framework/views.py", line 509, in dispatch
    response = self.handle_exception(exc)
  File "/usr/local/lib/python3.7/site-packages/rest_framework/views.py", line 469, in handle_exception
    self.raise_uncaught_exception(exc)
  File "/usr/local/lib/python3.7/site-packages/rest_framework/views.py", line 480, in raise_uncaught_exception
    raise exc
  File "/usr/local/lib/python3.7/site-packages/rest_framework/views.py", line 506, in dispatch
    response = handler(request, *args, **kwargs)
  File "/app/pets/views/pets.py", line 62, in get
    return self.retrieve(request, *args, **kwargs)
  File "/usr/local/lib/python3.7/site-packages/rest_framework/mixins.py", line 54, in retrieve
    instance = self.get_object()
  File "/usr/local/lib/python3.7/site-packages/rest_framework/generics.py", line 99, in get_object
    self.check_object_permissions(self.request, obj)
  File "/usr/local/lib/python3.7/site-packages/rest_framework/views.py", line 345, in check_object_permissions
    if not permission.has_object_permission(request, self, obj):
  File "/app/pets/permissions.py", line 13, in has_object_permission
    if request.method in self.SAFE_METHODS and user in obj.recipients.all():
AttributeError: 'Pet' object has no attribute 'recipients'
ERROR 2021-06-30 12:45:32,505 log 18 140492594870016 Internal Server Error: /pets/1/
Traceback (most recent call last):
  File "/usr/local/lib/python3.7/site-packages/django/core/handlers/exception.py", line 47, in inner
    response = get_response(request)
  File "/usr/local/lib/python3.7/site-packages/django/core/handlers/base.py", line 181, in _get_response
    response = wrapped_callback(request, *callback_args, **callback_kwargs)
  File "/usr/local/lib/python3.7/site-packages/django/views/decorators/csrf.py", line 54, in wrapped_view
    return view_func(*args, **kwargs)
  File "/usr/local/lib/python3.7/site-packages/django/views/generic/base.py", line 70, in view
    return self.dispatch(request, *args, **kwargs)
  File "/usr/local/lib/python3.7/site-packages/rest_framework/views.py", line 509, in dispatch
    response = self.handle_exception(exc)
  File "/usr/local/lib/python3.7/site-packages/rest_framework/views.py", line 469, in handle_exception
    self.raise_uncaught_exception(exc)
  File "/usr/local/lib/python3.7/site-packages/rest_framework/views.py", line 480, in raise_uncaught_exception
    raise exc
  File "/usr/local/lib/python3.7/site-packages/rest_framework/views.py", line 506, in dispatch
    response = handler(request, *args, **kwargs)
  File "/app/pets/views/pets.py", line 62, in get
    return self.retrieve(request, *args, **kwargs)
  File "/usr/local/lib/python3.7/site-packages/rest_framework/mixins.py", line 54, in retrieve
    instance = self.get_object()
  File "/usr/local/lib/python3.7/site-packages/rest_framework/generics.py", line 99, in get_object
    self.check_object_permissions(self.request, obj)
  File "/usr/local/lib/python3.7/site-packages/rest_framework/views.py", line 345, in check_object_permissions
    if not permission.has_object_permission(request, self, obj):
  File "/app/pets/permissions.py", line 13, in has_object_permission
    if request.method in self.SAFE_METHODS and user in obj.recipients.all():
AttributeError: 'Pet' object has no attribute 'recipients'
ERROR 2021-06-30 12:45:41,862 log 18 140492594870016 Internal Server Error: /pets/1/
Traceback (most recent call last):
  File "/usr/local/lib/python3.7/site-packages/django/core/handlers/exception.py", line 47, in inner
    response = get_response(request)
  File "/usr/local/lib/python3.7/site-packages/django/core/handlers/base.py", line 181, in _get_response
    response = wrapped_callback(request, *callback_args, **callback_kwargs)
  File "/usr/local/lib/python3.7/site-packages/django/views/decorators/csrf.py", line 54, in wrapped_view
    return view_func(*args, **kwargs)
  File "/usr/local/lib/python3.7/site-packages/django/views/generic/base.py", line 70, in view
    return self.dispatch(request, *args, **kwargs)
  File "/usr/local/lib/python3.7/site-packages/rest_framework/views.py", line 509, in dispatch
    response = self.handle_exception(exc)
  File "/usr/local/lib/python3.7/site-packages/rest_framework/views.py", line 469, in handle_exception
    self.raise_uncaught_exception(exc)
  File "/usr/local/lib/python3.7/site-packages/rest_framework/views.py", line 480, in raise_uncaught_exception
    raise exc
  File "/usr/local/lib/python3.7/site-packages/rest_framework/views.py", line 506, in dispatch
    response = handler(request, *args, **kwargs)
  File "/app/pets/views/pets.py", line 62, in get
    return self.retrieve(request, *args, **kwargs)
  File "/usr/local/lib/python3.7/site-packages/rest_framework/mixins.py", line 54, in retrieve
    instance = self.get_object()
  File "/usr/local/lib/python3.7/site-packages/rest_framework/generics.py", line 99, in get_object
    self.check_object_permissions(self.request, obj)
  File "/usr/local/lib/python3.7/site-packages/rest_framework/views.py", line 345, in check_object_permissions
    if not permission.has_object_permission(request, self, obj):
  File "/app/pets/permissions.py", line 13, in has_object_permission
    if request.method in self.SAFE_METHODS and user in obj.recipients.all():
AttributeError: 'Pet' object has no attribute 'recipients'
